2025-09-18 18:00:03,152 INFO    MainThread:1192 [wandb_setup.py:_flush():81] Current SDK version is 0.21.4
2025-09-18 18:00:03,152 INFO    MainThread:1192 [wandb_setup.py:_flush():81] Configure stats pid to 1192
2025-09-18 18:00:03,153 INFO    MainThread:1192 [wandb_setup.py:_flush():81] Loading settings from C:\Users\sabry\.config\wandb\settings
2025-09-18 18:00:03,153 INFO    MainThread:1192 [wandb_setup.py:_flush():81] Loading settings from C:\Users\sabry\Documents\Citylearn_dinamics\wandb\settings
2025-09-18 18:00:03,153 INFO    MainThread:1192 [wandb_setup.py:_flush():81] Loading settings from environment variables
2025-09-18 18:00:03,153 INFO    MainThread:1192 [wandb_init.py:setup_run_log_directory():686] Logging user logs to C:\Users\sabry\Documents\Citylearn_dinamics\wandb\run-20250918_180003-gpl0jj5e\logs\debug.log
2025-09-18 18:00:03,154 INFO    MainThread:1192 [wandb_init.py:setup_run_log_directory():687] Logging internal logs to C:\Users\sabry\Documents\Citylearn_dinamics\wandb\run-20250918_180003-gpl0jj5e\logs\debug-internal.log
2025-09-18 18:00:03,154 INFO    MainThread:1192 [wandb_init.py:init():813] calling init triggers
2025-09-18 18:00:03,155 INFO    MainThread:1192 [wandb_init.py:init():818] wandb.init called with sweep_config: {}
config: {'dataset': 'C:\\Users\\sabry\\Documents\\Citylearn_dinamics\\data\\CA_10_dynamics\\schema.json', 'dataset_mode': 'local', 'central_agent': False, 'episodes': 10, 'lr': 0.001, 'beta': 0.0, 'output_root': 'C:\\Users\\sabry\\Documents\\Citylearn_dinamics\\outputs', 'zip_path': 'C:\\Users\\sabry\\Documents\\Citylearn_dinamics\\outputs\\CA_10_dynamics\\save_models\\aac_madrl\\beta=0.0_gamma=1.0\\lr=0.001\\aac_madrl.zip', 'data_dir': 'C:\\Users\\sabry\\.citylearn\\data', 'sim_start': 0, 'sim_end': 743, 'classes': {'dhw_storage': 21, 'electrical_storage': 21, 'cooling_or_heating_device': 21}, '_wandb': {}}
2025-09-18 18:00:03,155 INFO    MainThread:1192 [wandb_init.py:init():854] starting backend
2025-09-18 18:00:05,660 INFO    MainThread:1192 [wandb_init.py:init():857] sending inform_init request
2025-09-18 18:00:05,685 INFO    MainThread:1192 [wandb_init.py:init():865] backend started and connected
2025-09-18 18:00:05,691 INFO    MainThread:1192 [wandb_init.py:init():936] updated telemetry
2025-09-18 18:00:05,836 INFO    MainThread:1192 [wandb_init.py:init():960] communicating run to backend with 90.0 second timeout
2025-09-18 18:00:06,434 INFO    MainThread:1192 [wandb_init.py:init():1011] starting run threads in backend
2025-09-18 18:00:06,806 INFO    MainThread:1192 [wandb_run.py:_console_start():2506] atexit reg
2025-09-18 18:00:06,807 INFO    MainThread:1192 [wandb_run.py:_redirect():2354] redirect: wrap_raw
2025-09-18 18:00:06,808 INFO    MainThread:1192 [wandb_run.py:_redirect():2423] Wrapping output streams.
2025-09-18 18:00:06,809 INFO    MainThread:1192 [wandb_run.py:_redirect():2446] Redirects installed.
2025-09-18 18:00:06,820 INFO    MainThread:1192 [wandb_init.py:init():1049] run started, returning control to user process
2025-09-18 18:20:11,596 ERROR   wandb-AsyncioManager-main:1192 [service_client.py:_forward_responses():81] Error reading server response.
Traceback (most recent call last):
  File "C:\Users\sabry\AppData\Local\Programs\Python\Python39\lib\asyncio\windows_events.py", line 457, in finish_recv
    return ov.getresult()
OSError: [WinError 64] Il nome di rete specificato non è più disponibile

During handling of the above exception, another exception occurred:

Traceback (most recent call last):
  File "c:\Users\sabry\Documents\Citylearn_dinamics\.venv\lib\site-packages\wandb\sdk\lib\service\service_client.py", line 77, in _forward_responses
    while response := await self._read_server_response():
  File "c:\Users\sabry\Documents\Citylearn_dinamics\.venv\lib\site-packages\wandb\sdk\lib\service\service_client.py", line 91, in _read_server_response
    header = await self._reader.readexactly(_HEADER_BYTE_INT_LEN)
  File "C:\Users\sabry\AppData\Local\Programs\Python\Python39\lib\asyncio\streams.py", line 723, in readexactly
    await self._wait_for_data('readexactly')
  File "C:\Users\sabry\AppData\Local\Programs\Python\Python39\lib\asyncio\streams.py", line 517, in _wait_for_data
    await self._waiter
  File "C:\Users\sabry\AppData\Local\Programs\Python\Python39\lib\asyncio\proactor_events.py", line 280, in _loop_reading
    data = fut.result()
  File "C:\Users\sabry\AppData\Local\Programs\Python\Python39\lib\asyncio\windows_events.py", line 812, in _poll
    value = callback(transferred, key, ov)
  File "C:\Users\sabry\AppData\Local\Programs\Python\Python39\lib\asyncio\windows_events.py", line 461, in finish_recv
    raise ConnectionResetError(*exc.args)
ConnectionResetError: [WinError 64] Il nome di rete specificato non è più disponibile
2025-09-18 18:20:11,630 INFO    wandb-AsyncioManager-main:1192 [mailbox.py:close():137] Closing mailbox, abandoning 1 handles.
