2025-09-19 09:40:23,291 INFO    MainThread:3768 [wandb_setup.py:_flush():81] Current SDK version is 0.21.4
2025-09-19 09:40:23,293 INFO    MainThread:3768 [wandb_setup.py:_flush():81] Configure stats pid to 3768
2025-09-19 09:40:23,293 INFO    MainThread:3768 [wandb_setup.py:_flush():81] Loading settings from C:\Users\sabry\.config\wandb\settings
2025-09-19 09:40:23,293 INFO    MainThread:3768 [wandb_setup.py:_flush():81] Loading settings from C:\Users\sabry\Documents\Citylearn_dinamics\wandb\settings
2025-09-19 09:40:23,293 INFO    MainThread:3768 [wandb_setup.py:_flush():81] Loading settings from environment variables
2025-09-19 09:40:23,293 INFO    MainThread:3768 [wandb_init.py:setup_run_log_directory():686] Logging user logs to C:\Users\sabry\Documents\Citylearn_dinamics\wandb\run-20250919_094023-i1eaha60\logs\debug.log
2025-09-19 09:40:23,294 INFO    MainThread:3768 [wandb_init.py:setup_run_log_directory():687] Logging internal logs to C:\Users\sabry\Documents\Citylearn_dinamics\wandb\run-20250919_094023-i1eaha60\logs\debug-internal.log
2025-09-19 09:40:23,294 INFO    MainThread:3768 [wandb_init.py:init():813] calling init triggers
2025-09-19 09:40:23,295 INFO    MainThread:3768 [wandb_init.py:init():818] wandb.init called with sweep_config: {}
config: {'dataset': 'C:\\Users\\sabry\\Documents\\Citylearn_dinamics\\data\\TX_50_dynamics\\schema.json', 'dataset_mode': 'local', 'central_agent': False, 'episodes': 10, 'lr': 0.001, 'beta': 0.0, 'gamma': 3.5, 'output_root': 'C:\\Users\\sabry\\Documents\\Citylearn_dinamics\\outputs', 'zip_path': 'C:\\Users\\sabry\\Documents\\Citylearn_dinamics\\outputs\\TX_50_dynamics\\save_models\\sac\\beta=0.0_gamma=3.5\\lr=0.001\\sac.zip', 'data_dir': 'C:\\Users\\sabry\\.citylearn\\data', 'sim_start': 3624, 'sim_end': 4343, '_wandb': {}}
2025-09-19 09:40:23,295 INFO    MainThread:3768 [wandb_init.py:init():854] starting backend
2025-09-19 09:40:25,584 INFO    MainThread:3768 [wandb_init.py:init():857] sending inform_init request
2025-09-19 09:40:25,596 INFO    MainThread:3768 [wandb_init.py:init():865] backend started and connected
2025-09-19 09:40:25,602 INFO    MainThread:3768 [wandb_init.py:init():936] updated telemetry
2025-09-19 09:40:25,728 INFO    MainThread:3768 [wandb_init.py:init():960] communicating run to backend with 90.0 second timeout
2025-09-19 09:40:26,270 INFO    MainThread:3768 [wandb_init.py:init():1011] starting run threads in backend
2025-09-19 09:40:26,547 INFO    MainThread:3768 [wandb_run.py:_console_start():2506] atexit reg
2025-09-19 09:40:26,547 INFO    MainThread:3768 [wandb_run.py:_redirect():2354] redirect: wrap_raw
2025-09-19 09:40:26,548 INFO    MainThread:3768 [wandb_run.py:_redirect():2423] Wrapping output streams.
2025-09-19 09:40:26,549 INFO    MainThread:3768 [wandb_run.py:_redirect():2446] Redirects installed.
2025-09-19 09:40:26,560 INFO    MainThread:3768 [wandb_init.py:init():1049] run started, returning control to user process
2025-09-19 09:40:28,693 INFO    wandb-AsyncioManager-main:3768 [service_client.py:_forward_responses():84] Reached EOF.
2025-09-19 09:40:28,693 INFO    wandb-AsyncioManager-main:3768 [mailbox.py:close():137] Closing mailbox, abandoning 1 handles.
2025-09-19 09:40:29,760 ERROR   wandb-AsyncioManager-main:3768 [asyncio_manager.py:fn_wrap_exceptions():183] Uncaught exception in run_soon callback.
Traceback (most recent call last):
  File "c:\Users\sabry\Documents\Citylearn_dinamics\.venv\lib\site-packages\wandb\sdk\lib\asyncio_manager.py", line 181, in fn_wrap_exceptions
    await fn()
  File "c:\Users\sabry\Documents\Citylearn_dinamics\.venv\lib\site-packages\wandb\sdk\lib\service\service_client.py", line 65, in _send_server_request
    await self._writer.drain()
  File "C:\Users\sabry\AppData\Local\Programs\Python\Python39\lib\asyncio\streams.py", line 387, in drain
    await self._protocol._drain_helper()
  File "C:\Users\sabry\AppData\Local\Programs\Python\Python39\lib\asyncio\streams.py", line 190, in _drain_helper
    raise ConnectionResetError('Connection lost')
ConnectionResetError: Connection lost
2025-09-19 09:40:29,791 ERROR   wandb-AsyncioManager-main:3768 [asyncio_manager.py:fn_wrap_exceptions():183] Uncaught exception in run_soon callback.
Traceback (most recent call last):
  File "c:\Users\sabry\Documents\Citylearn_dinamics\.venv\lib\site-packages\wandb\sdk\lib\asyncio_manager.py", line 181, in fn_wrap_exceptions
    await fn()
  File "c:\Users\sabry\Documents\Citylearn_dinamics\.venv\lib\site-packages\wandb\sdk\lib\service\service_client.py", line 65, in _send_server_request
    await self._writer.drain()
  File "C:\Users\sabry\AppData\Local\Programs\Python\Python39\lib\asyncio\streams.py", line 387, in drain
    await self._protocol._drain_helper()
  File "C:\Users\sabry\AppData\Local\Programs\Python\Python39\lib\asyncio\streams.py", line 190, in _drain_helper
    raise ConnectionResetError('Connection lost')
ConnectionResetError: Connection lost
